# 第二次问题诊断与分析报告

[模式: 研究], [AI模型: Gemini 2.5 Pro]

在第一轮修复结束后，我们运行了完整的测试套件，但遇到了新的问题。本报告将记录这些新发现的问题。

## 1. 测试环境崩溃 (`ImportError`)

-   **现象**: `pytest` 命令在收集测试用例之前就因 `ImportError` 而崩溃。
-   **错误日志**: 
    ```
    ImportError: cannot import name 'display_covered' from 'coverage.results'
    ```
-   **根本原因**: 经过分析，此问题是由于 `pytest-cov` 和 `coverage` 两个库之间的版本不兼容导致的。项目中使用的 `pytest-cov` 版本过旧，它所依赖的 `display_covered` 函数在较新版本的 `coverage` 库中已被移除。
-   **解决方案**: 升级 `pytest-cov` 库到最新版本，以确保它与系统中已安装的 `coverage` 库兼容。

## 2. 模块未找到 (`ModuleNotFoundError`)

-   **现象**: 修复环境问题后，`pytest` 在加载 `tests/conftest.py` 时因 `ModuleNotFoundError` 而失败。
-   **错误日志**:
    ```
    ImportError while loading conftest '/Users/hacker/PycharmProjects/freedom/tests/conftest.py'.
    tests/conftest.py:16: in <module>
        from utils.logger import setup_logger
    E   ModuleNotFoundError: No module named 'utils'
    ```
-   **根本原因**: 这是 Python 路径问题。`pytest` 运行时，项目的根目录未被添加到模块搜索路径 (`sys.path`) 中，导致无法找到 `utils` 等项目模块。
-   **解决方案**: 在 `tests/conftest.py` 的顶部添加代码，动态地将项目根目录插入到 `sys.path` 中。这确保了在所有测试运行之前，项目的模块都是可导入的。

## 3. 模块路径不正确 (`ModuleNotFoundError`)

-   **现象**: `pytest` 在收集 `tests/performance/test_data_manager_performance.py` 时失败。
-   **错误日志**: `ModuleNotFoundError: No module named 'data.data_manager'`
-   **根本原因**: 测试文件试图从 `data.data_manager` 导入 `DataManager`。根据项目架构，`DataManager` 明确位于 `db` 模块中，即 `db.data_manager`。这是一个错误的导入路径。
-   **解决方案**: 纠正导入语句，将 `from data.data_manager import DataManager` 修改为 `from db.data_manager import DataManager`。

## 4. 模块内成员缺失 (`ImportError`)

-   **现象**: `pytest` 在收集 `tests/unit/test_indicators.py` 时失败。
-   **错误日志**: `ImportError: cannot import name 'EMA' from 'indicators.ma'`
-   **根本原因**: 测试文件试图从 `indicators/ma.py` 模块中导入 `EMA` 类。这个错误的发生，是因为在上一轮修复中，我为了解决 `NameError` 而添加了此 `import` 语句，但我错误地假设了 `EMA` 类存在于 `ma.py` 文件中。实际上，`ma.py` 很可能只包含 `MA`（简单移动平均线）的实现，而 `EMA`（指数移动平均线）要么在别的文件里，要么其定义方式与预期不符。
-   **解决方案**:
    1.  调查 `EMA` 指标的实际位置。我需要搜索 `indicators` 目录来确定 `EMA` 类的确切文件名和位置。
    2.  根据调查结果，修正 `tests/unit/test_indicators.py` 中的 `import` 语句。

## 5. 大规模测试失败的系统性原因

在修复了导入问题后，`pytest` 得以运行完整的测试套件，但结果揭示了几个系统性的问题，导致了超过700个测试失败。

### 5.1. 接口不完整 (`TypeError`)

-   **现象**: 大量的测试因 `TypeError: Can't instantiate abstract class ... with abstract method set_parameters` 而失败。
-   **根本原因**: 在第一轮修复中，`set_parameters` 被添加为 `BaseIndicator` 的一个抽象方法。这导致所有未实现此方法的指标子类在测试中尝试实例化时都会失败。这是最普遍的错误，影响了几乎所有的指标。
-   **解决方案**: 系统性地为所有继承自 `BaseIndicator` 但缺少 `set_parameters` 方法的类添加一个标准的存根实现。

### 5.2. 指标未在工厂注册 (`IndicatorNotFoundError`)

-   **现象**: `IndicatorFactory` 无法创建 `TRENDCLASSIFICATION`, `TRENDSTRENGTH`, `CMO` 等指标。
-   **根本原因**: 这些指标类没有在 `indicators/factory.py` 中被导入和注册。
-   **解决方案**: 找到这些指标的定义文件，并在工厂文件中导入它们。

### 5.3. 数据访问层及其测试中的 `AttributeError`

-   **现象**: `test_data_manager.py` 中的测试因属性错误而失败。
-   **根本原因**:
    1.  `get_kline_data` 方法试图访问 `StockInfo` 对象上不存在的 `.data` 属性。
    2.  测试代码调用了 `DataManager` 上不存在的 `.get_stock_list` 方法。
-   **解决方案**:
    1.  检查 `models/stock_info.py` 并修正 `get_kline_data` 的实现。
    2.  将测试中对 `get_stock_list` 的调用替换为正确的方法。

### 5.4. 测试辅助工具不完善 (`AttributeError`)

-   **现象**: `test_boll.py` 中的所有测试都因 `AttributeError: type object 'TestDataGenerator' has no attribute 'generate_steady_trend'` 而失败。
-   **根本原因**: `tests/helper/data_generator.py` 中缺少测试用例所需的辅助方法。
-   **解决方案**: 在 `TestDataGenerator` 类中实现 `generate_steady_trend` 方法。 